Workbook

Sheet +1 Year Product Demand
A1: Georgia Tech ISYE 6202 + 6336 FALL 2025
A2: Professor Benoit Montreuil
A3: CASEWORK 3: FaMoaSa FaMoaSa Manufacturing & Warehousing Facility Design
A4: Year +1 Product Demand from Client Assembly Factory
B16: Year +1 Demand Forecast for Each Product of Clients A and B
B17: Year | C17: A1 | D17: A2 | E17: A3 | F17: B1 | G17: B2 | H17: Total
B18: +1 | C18: 50000 | D18: 100000 | E18: 130000 | F18: 60000 | G18: 80000 | H18: =SUM(C18:G18) -> 420000
B21: Standard Deviation on Year +1 Demand Forecast for Each Product of Clients A and B
B22: Year | C22: A1 | D22: A2 | E22: A3 | F22: B1 | G22: B2 | H22: Overall
B23: +1 | C23: 721.11026 | D23: 1442.2205 | E23: 2163.3308 | F23: 1442.2205 | G23: 721.11026 | H23: 447
B26: Year +1 Weekly Demand Forecast for Each Product of Clients A and B
B27: Year | C27: A1 | D27: A2 | E27: A3 | F27: B1 | G27: B2 | H27: Total
B28: +1 | C28: =C18/52 -> 961.53846 | D28: =D18/52 -> 1923.0769 | E28: =E18/52 -> 2500 | F28: =F18/52 -> 1153.8462 | G28: =G18/52 -> 1538.4615 | H28: =SUM(C28:G28) -> 8076.9231 | P28: =SQRT(P27) -> 0
B30: Expected Coefficient of Variation of Weekly Year +1 Demand for Each Product of Clients A and B
B31: Year | C31: A1 | D31: A2 | E31: A3 | F31: B1 | G31: B2 | H31: Average
B32: +1 | C32: 0.15 | D32: 0.2 | E32: 0.2 | F32: 0.12 | G32: 0.18 | H32: =AVERAGE(C32:G32) -> 0.17

Sheet +1 Year Parts per Product
A1: Georgia Tech ISYE 6202 + 6336 FALL 2025
A2: Professor Benoit Montreuil
A3: CASEWORK 3: FaMoaSa FaMoaSa Manufacturing & Warehousing Facility Design
A4: Year +1 Parts Demand induced by Product Demand from Client Assembly Factory
B10: Part | C10: Parts per Assembled Product Unit Demanded in Year +1
C11: A1 | D11: A2 | E11: A3 | F11: B1 | G11: B2
B12: P1 | C12: 1 | D12: 2 | E12: 4 | F12: 4 | G12: 1
B13: P2 | C13: 4 | E13: 2 | F13: 2
B14: P3 | F14: 4 | G14: 1
B15: P4 | D15: 1 | E15: 2 | F15: 2
B16: P5 | D16: 1 | E16: 2
B17: P6 | C17: 1 | G17: 2
B18: P7 | D18: 4 | G18: 4
B19: P8 | F19: 4
B20: P9 | D20: 2 | E20: 2
B21: P10 | C21: 1 | E21: 1 | F21: 1
B22: P11 | C22: 2 | G22: 4
B23: P12 | C23: 4 | G23: 4
B24: P13 | C24: 2 | G24: 2
B25: P14 | D25: 4 | E25: 2 | F25: 2 | G25: 2
B26: P15 | F26: 2
B27: P16 | D27: 1 | E27: 4
B28: P17 | C28: 2 | G28: 2
B29: P18 | C29: 4 | D29: 1 | G29: 4
B30: P19 | D30: 2 | E30: 4 | F30: 4 | G30: 1
B31: P20 | D31: 2 | E31: 3 | F31: 3

Sheet Parts Specs
A1: Georgia Tech ISYE 6202 + 6336 FALL 2025
A2: Professor Benoit Montreuil
A3: CASEWORK 3: FaMoaSa FaMoaSa Manufacturing & Warehousing Facility Design
A4: Parts Specifications
B10: Part | C10: Process
C11: Step 1 | D11: Step 2 | E11: Step 3 | F11: Step 4 | G11: Step 5 | H11: Step 6 | I11: Step 7
B12: P1 | C12: B | D12: A | E12: B | F12: C | G12: D | H12: I | I12: J
B13: P2 | C13: A | D13: C | E13: D | F13: H | G13: J
B14: P3 | C14: B | D14: D | E14: C | F14: I | G14: J
B15: P4 | C15: A | D15: B | E15: D | F15: G | G15: H
B16: P5 | C16: B | D16: C | E16: D | F16: I
B17: P6 | C17: A | D17: B | E17: C | F17: D | G17: H | H17: I | I17: J
B18: P7 | C18: E | D18: F | E18: C | F18: D | G18: I | H18: J
B19: P8 | C19: E | D19: H | E19: J | F19: I
B20: P9 | C20: F | D20: G | E20: E | F20: G | G20: I | H20: J
B21: P10 | C21: E | D21: F | E21: I | F21: J
B22: P11 | C22: E | D22: G | E22: E | F22: G | G22: I
B23: P12 | C23: E | D23: G | E23: F | F23: I | G23: J
B24: P13 | C24: E | D24: F | E24: G | F24: F | G24: G | H24: H | I24: I
B25: P14 | C25: E | D25: F | E25: G | F25: H
B26: P15 | C26: E | D26: G | E26: F | F26: H | G26: J
B27: P16 | C27: F | D27: H | E27: I | F27: J
B28: P17 | C28: K | D28: L | E28: M
B29: P18 | C29: K | D29: L | E29: K | F29: M
B30: P19 | C30: L | D30: M | E30: L | F30: M
B31: P20 | C31: L | D31: K | E31: M
B34: Part | C34: Dimensions | G34: Materials
B35: Identifier | C35: X (in.) | D35: Y (in.) | E35: Z (in.) | F35: Weight (lbs) | G35: Price/unit
B36: P1 | C36: 2 | D36: 6 | E36: 6 | F36: 2 | G36: 12
B37: P2 | C37: 8 | D37: 8 | E37: 4 | F37: 14 | G37: 100
B38: P3 | C38: 6 | D38: 6 | E38: 6 | F38: 6 | G38: 50
B39: P4 | C39: 12 | D39: 6 | E39: 4 | F39: 16 | G39: 120
B40: P5 | C40: 8 | D40: 4 | E40: 6 | F40: 5 | G40: 50
B41: P6 | C41: 2 | D41: 8 | E41: 6 | F41: 3 | G41: 15
B42: P7 | C42: 2 | D42: 2 | E42: 12 | F42: 1 | G42: 25
B43: P8 | C43: 4 | D43: 4 | E43: 4 | F43: 1 | G43: 20
B44: P9 | C44: 2 | D44: 4 | E44: 12 | F44: 2 | G44: 40
B45: P10 | C45: 4 | D45: 4 | E45: 4 | F45: 1 | G45: 20
B46: P11 | C46: 4 | D46: 6 | E46: 4 | F46: 2 | G46: 30
B47: P12 | C47: 6 | D47: 6 | E47: 4 | F47: 2 | G47: 30
...

Sheet Equip+Operator Specs
A1: Georgia Tech ISYE 6202 + 6336 FALL 2025
A2: Professor Benoit Montreuil
A3: CASEWORK 3: FaMoaSa FaMoaSa Manufacturing & Warehousing Facility Design
A4: Equipment & Operator Specifications
B10: Equipment | C10: Installed price | D10: Relocation cost | E10: Useful life (years) | F10: Number of operators | H10: Operator | I10: Hourly Cost
H11: C1 | I11: 20
B12: A | C12: 150000 | D12: 10000 | E12: 10 | F12: 1 C1+1/4 C2 | H12: C2 | I12: 40
B13: B | C13: 200000 | D13: 10000 | E13: 10 | F13: 1 C1+1/4 C2 | H13: C3 | I13: 60
B14: C | C14: 250000 | D14: 10000 | E14: 10 | F14: 1 C1+1/4 C2
B15: D | C15: 300000 | D15: 10000 | E15: 10 | F15: 1 C1+1/4 C2
B16: AB | C16: 250000 | D16: 10000 | E16: 10 | F16: 1 C1+1/4 C2
B17: AC | C17: 280000 | D17: 10000 | E17: 10 | F17: 1 C1+1/4 C2
B18: CD | C18: 350000 | D18: 10000 | E18: 10 | F18: 1 C1+1/4 C2
B19: ABC | C19: 300000 | D19: 10000 | E19: 10 | F19: 1 C1+1/4 C2
B20: ABCD | C20: 400000 | D20: 10000 | E20: 10 | F20: 1 C1+1/4 C2
B21: E | C21: 400000 | D21: 50000 | E21: 10 | F21: 1 C1 + 1/2 C3
B22: F | C22: 400000 | D22: 50000 | E22: 10 | F22: 1 C1 + 1/2 C3
B23: G | C23: 400000 | D23: 50000 | E23: 10 | F23: 1 C1 + 1/2 C3
B24: EF | C24: 450000 | D24: 50000 | E24: 10 | F24: 1 C1 + 1/2 C3
B25: EG | C25: 450000 | D25: 50000 | E25: 10 | F25: 1 C1 + 1/2 C3
... B38: KLM | C38: 150000 | D38: 2000 | E38: 8 | F38: 1/2 C2

Sheet Basic Layouts
A1: Georgia Tech ISYE 6202 + 6336 FALL 2025
A2: Professor Benoit Montreuil
A3: CASEWORK 3: FaMoaSa FaMoaSa Manufacturing & Warehousing Facility Design
A4: Basic Layouts
Y5: 14 feet *14 feet spacial envelope
Y6: 2 feet sharable with others | AL6: 2 feet sharable with others
I8: 14 feet *7 feet spacial envelope | AB8: 7 feet * 8 feet
O9: Inbound Outbound | AB9: A-B-C-D Category Equipment
F10: 3 feet *6 feet
F11: K-L-M Category Equipment
J14: 1 foot sharable with others
AA16: Inbound Outbound
L17: 22 feet *15 feet spacial envelope
L19: Maintenance access
C20: Maintenance access | L20: 6 feet * 16 feet | V20: Maintenance access
F21: E-F-G Category Equipment
D29: Inbound | N29: Outbound
B34: 14 feet *36 feet spacial envelope
C35: Inbound | T35: Maintenance access | AI35: Outbound
H37: 5 feet * 24 feet
I38: H-I-J Category Equipment
T43: Maintenance access
N48: 11ft*11ft spacial envelope | V48: 11ft*15ft spacial envelope
J51: Parts feeder | Y51: Parts feeder
J53: 3ft*5ft Workbench | Y53: 3ft*9ft Workbench
G54: Cart with jig of next product | K54: Jig of product being assembled | O54: Cart with jig of assembled product | V54: Cart with jig of next product | Z54: Jig of product being assembled | AD54: Fixture ready to secure next jig | AH54: Cart with jig of assembled product
O57: Empty cart for current jig | AH57: Empty cart for current jig

Sheet +2 to +5 Year Product Demand 
A1: Georgia Tech ISYE 6202 + 6336 FALL 2025
A2: Professor Benoit Montreuil
A3: CASEWORK 3: FaMoaSa FaMoaSa Manufacturing & Warehousing Facility Design
A4: Year +2 to +5 Product Demand from Client Assembly Factory
B10: Yearly Demand Forecast for Each Product in the +2 to +5 Year Horizon
B11: Year | C11: A1 | D11: A2 | E11: A3 | F11: B1 | G11: B2 | H11: A4 | I11: B3 | J11: B4 | K11: Total
B12: +2 | C12: 78000 | D12: 104000 | E12: 140400 | F12: 72800 | G12: 93600 | H12: 52000 | I12: 26000 | J12: 62400 | K12: 629200
B13: +3 | C13: 62400 | D13: 78000 | E13: 150800 | F13: 83200 | G13: 109200 | H13: 78000 | I13: 52000 | J13: 78000 | K13: 691600
B14: +4 | C14: 46800 | D14: 52000 | E14: 161200 | F14: 93600 | G14: 124800 | H14: 104000 | I14: 78000 | J14: 93600 | K14: 754000
B15: +5 | C15: 26000 | D15: 26000 | E15: 171600 | F15: 104000 | G15: 140400 | H15: 156000 | I15: 104000 | J15: 114400 | K15: 842400
B18: Standard Deviation on Each Year's Demand Forecast for Each Product in the +2 to +5 Year Horizon
B19: Year | C19: A1 | D19: A2 | E19: A3 | F19: B1 | G19: B2 | H19: A4 | I19: B3 | J19: B4 | K19: Overall
B20: +2 | C20: 1442.2205 | D20: 1442.2205 | E20: 2884.441 | F20: 1802.7756 | G20: 1081.6654 | H20: 1442.2205 | I20: 721.11026 | J20: 540.83269 | K20: 4448.8763 | W20: ='+1 Year Product Demand'!C23*'+1 Year Product Demand'!C23 -> 520000 | X20: ='+1 Year Product Demand'!D23*'+1 Year Product Demand'!D23 -> 2080000 | Y20: ='+1 Year Product Demand'!E23*'+1 Year Product Demand'!E23 -> 4680000 | Z20: ='+1 Year Product Demand'!F23*'+1 Year Product Demand'!F23 -> 2080000 | AA20: ='+1 Year Product Demand'!G23*'+1 Year Product Demand'!G23 -> 520000
B21: +3 | C21: 721.11026 | D21: 1081.6654 | E21: 3605.5513 | F21: 2163.3308 | G21: 1442.2205 | H21: 2163.3308 | I21: 1297.9985 | J21: 793.22128 | K21: 5333.2917 | V21: 52 | W21: =W20*$V$21 -> 27040000 | X21: =X20*$V$21 -> 108160000 | Y21: =Y20*$V$21 -> 2.4336e+08 | Z21: =Z20*$V$21 -> 108160000 | AA21: =AA20*$V$21 -> 27040000
B22: +4 | C22: 721.11026 | D22: 1081.6654 | E22: 4326.6615 | F22: 2884.441 | G22: 1802.7756 | H22: 2884.441 | I22: 1442.2205 | J22: 901.38782 | K22: 6572.1001 | W22: =SQRT(W21) -> 5200 | X22: =SQRT(X21) -> 10400 | Y22: =SQRT(Y21) -> 15600 | Z22: =SQRT(Z21) -> 10400 | AA22: =SQRT(AA21) -> 5200
B23: +5 | C23: 721.11026 | D23: 721.11026 | E23: 5047.7718 | F23: 3605.5513 | G23: 2163.3308 | H23: 3605.5513 | I23: 1586.4426 | J23: 1081.6654 | K23: 7802.9994
B26: Expected Average Weekly Demand for Each Product in the +2 to +5 Year Horizon
B27: Year | C27: A1 | D27: A2 | E27: A3 | F27: B1 | G27: B2 | H27: A4 | I27: B3 | J27: B4 | K27: Total
B28: +2 | C28: 1500 | D28: 2000 | E28: 2700 | F28: 1400 | G28: 1800 | H28: 1000 | I28: 500 | J28: 1200 | K28: 12100
B29: +3 | C29: 1200 | D29: 1500 | E29: 2900 | F29: 1600 | G29: 2100 | H29: 1500 | I29: 1000 | J29: 1500 | K29: 13300
B30: +4 | C30: 900 | D30: 1000 | E30: 3100 | F30: 1800 | G30: 2400 | H30: 2000 | I30: 1500 | J30: 1800 | K30: 14500
B31: +5 | C31: 500 | D31: 500 | E31: 3300 | F31: 2000 | G31: 2700 | H31: 3000 | I31: 2000 | J31: 2200 | K31: 16200
B34: Expected Coefficient of Variation of Weekly Demand for Each Product in the +2 to +5 Year Horizon
B35: Year | C35: A1 | D35: A2 | E35: A3 | F35: B1 | G35: B2 | H35: A4 | I35: B3 | J35: B4 | K35: Average
B36: +2 | C36: 0.15 | D36: 0.2 | E36: 0.2 | F36: 0.12 | G36: 0.18 | H36: 0.25 | J36: 0.08 | K36: =AVERAGE(C36:J36) -> 0.16857143
B37: +3 | C37: 0.15 | D37: 0.2 | E37: 0.2 | F37: 0.12 | G37: 0.18 | H37: 0.25 | I37: 0.15 | J37: 0.08 | K37: =AVERAGE(C37:J37) -> 0.16625
B38: +4 | C38: 0.15 | D38: 0.2 | E38: 0.2 | F38: 0.12 | G38: 0.18 | H38: 0.25 | I38: 0.15 | J38: 0.08 | K38: =AVERAGE(C38:J38) -> 0.16625
B39: +5 | C39: 0.15 | D39: 0.2 | E39: 0.2 | F39: 0.12 | G39: 0.18 | H39: 0.25 | I39: 0.15 | J39: 0.08 | K39: =AVERAGE(C39:J39) -> 0.16625
B40: 2029 | C40: 0.15 | D40: 0.2 | E40: 0.2 | F40: 0.12 | G40: 0.18 | H40: 0.25 | I40: 0.15 | J40: 0.08 | K40: =AVERAGE(C40:J40) -> 0.16625
O58: 2025 Demand Forecast for Each Product
O59: Year | P59: A1 | Q59: A2 | R59: A3 | S59: A4 | T59: A5 | U59: Total
O60: 2025 | P60: 50000 | Q60: 100000 | R60: 130000 | S60: 60000 | T60: 80000 | U60: =SUM(P60:T60) -> 420000
O63: Standard Deviation on 2025 Demand Forecast for Each Product
O64: Year | P64: A1 | Q64: A2 | R64: A3 | S64: A4 | T64: A5 | U64: Overall
O65: 2025 | P65: 100 | Q65: 200 | R65: 300 | S65: 200 | T65: 100 | U65: 447
O69: Year | P69: A1 | Q69: A2 | R69: A3 | S69: A4 | T69: A5 | U69: Total
O70: 2025 | P70: =P60/52 -> 961.53846 | Q70: =Q60/52 -> 1923.0769 | R70: =R60/52 -> 2500 | S70: =S60/52 -> 1153.8462 | T70: =T60/52 -> 1538.4615 | U70: =SUM(P70:T70) -> 8076.9231
O72: Expected Coefficient of Variation of Weekly 2025 Demand for Each Product
O73: Year | P73: A1 | Q73: A2 | R73: A3 | S73: A4 | T73: A5 | U73: Average
O74: 2025 | P74: 0.15 | Q74: 0.2 | R74: 0.2 | S74: 0.12 | T74: 0.18 | U74: =AVERAGE(P74:T74) -> 0.17

Sheet +2 to +5 Year Parts per Product
A1: Georgia Tech ISYE 6202 + 6336 FALL 2025
A2: Professor Benoit Montreuil
A3: CASEWORK 3: FaMoaSa FaMoaSa Manufacturing & Warehousing Facility Design
A4: Year +2 to +5 Parts Demand induced by Product Demand from Client Assembly Factories A and B
B10: Part | C10: Number of Parts per Assembled Product Unit Planned to be Demanded in 2026-2029 by Clients A and B
C11: A1 | D11: A2 | E11: A3 | F11: B1 | G11: B2 | H11: A4 | I11: B3 | J11: B4
B12: P1 | C12: 1 | D12: 2 | E12: 4 | F12: 4 | G12: 1 | J12: 2
B13: P2 | C13: 4 | E13: 2 | F13: 2 | J13: 1
B14: P3 | F14: 4 | G14: 1 | H14: 2 | I14: 4 | J14: 1
B15: P4 | D15: 1 | E15: 2 | F15: 2
B16: P5 | D16: 1 | E16: 2 | H16: 1 | I16: 1
B17: P6 | C17: 1 | G17: 2 | J17: 3
B18: P7 | D18: 4 | G18: 4 | I18: 1 | J18: 1
B19: P8 | F19: 4 | H19: 2 | I19: 2 | J19: 3
B20: P9 | D20: 2 | E20: 2 | H20: 1 | I20: 2
B21: P10 | C21: 1 | E21: 1 | F21: 1 | J21: 1
B22: P11 | C22: 2 | G22: 4 | H22: 4 | I22: 2
B23: P12 | C23: 4 | G23: 4 | H23: 3 | I23: 4
B24: P13 | C24: 2 | G24: 2 | H24: 2 | I24: 1
B25: P14 | D25: 4 | E25: 2 | F25: 2 | G25: 2 | J25: 4
B26: P15 | F26: 2 | H26: 2 | J26: 1
B27: P16 | D27: 1 | E27: 4
B28: P17 | C28: 2 | G28: 2 | H28: 2 | I28: 2 | J28: 1
B29: P18 | C29: 4 | D29: 1 | G29: 4 | H29: 1 | I29: 3
B30: P19 | D30: 2 | E30: 4 | F30: 4 | G30: 1 | J30: 3
B31: P20 | D31: 2 | E31: 3 | F31: 3 | J31: 4
